<?xml version="1.0" ?>
<robot name="shadowhand">
  <material name="Blue">
    <color rgba="0.0 0.0 0.8 1.0" />
  </material>
  <material name="Green">
    <color rgba="0.0 0.8 0.0 1.0" />
  </material>
  <material name="Grey">
    <color rgba="0.2 0.2 0.2 1.0" />
  </material>
  <material name="LightGrey">
    <color rgba="0.6 0.6 0.6 1.0" />
  </material>
  <material name="Red">
    <color rgba="0.8 0.0 0.0 1.0" />
  </material>
  <material name="White">
    <color rgba="1.0 1.0 1.0 1.0" />
  </material>
  
   <!-- ly modified -->
  <link name="world"></link>

  <joint name="world_to_base" type="fixed">
    <axis xyz="0 0 0"/>
    <origin xyz="0.0 0.0 0.0"/>
    <parent link="world"/>
    <child link="allegro_root0"/>
  </joint>

  <!-- ly modified -->
  <link name="allegro_root0">
    <inertial>
      <origin rpy="0 0 0" xyz="0 0 0"/>
      <mass value="0.00000"/>
       <inertia ixx="0" ixy="0.0" ixz="0.0" iyy="0" iyz="0.0" izz="0"/>   <!-- ly modified -->
      <!-- <inertia ixx="1.0" ixy="0.0" ixz="0.0" iyy="1.0" iyz="0.0" izz="1.0"/> --> 
    </inertial>
  </link>
  <link name="allegro_root1">
    <inertial>
      <mass value="0.00"/>
       <inertia ixx="0" ixy="0.0" ixz="0.0" iyy="0" iyz="0.0" izz="0"/>   <!-- ly modified -->
      <!-- <inertia ixx="0.00043" ixy="0" ixz="0" iyy="0.00029" iyz="0" izz="0.00020"/> --> 
    </inertial>
  </link>
  <link name="allegro_root2">
    <inertial>
      <mass value="0.0"/>
       <inertia ixx="0" ixy="0.0" ixz="0.0" iyy="0" iyz="0.0" izz="0"/>   <!-- ly modified -->
      <!-- <inertia ixx="0.00000" ixy="0" ixz="0" iyy="0.00000" iyz="0" izz="0.00000"/> -->
    </inertial>
  </link>
  <link name="allegro_root3">
    <inertial>
      <mass value="0.0"/>
       <inertia ixx="0" ixy="0.0" ixz="0.0" iyy="0" iyz="0.0" izz="0"/>   <!-- ly modified -->
      <!--  <inertia ixx="0.00000" ixy="0" ixz="0" iyy="0.00000" iyz="0" izz="0.00000"/> --> 
    </inertial>
  </link>
  <link name="allegro_root4">
    <inertial>
      <mass value="0.0"/>
       <inertia ixx="0" ixy="0.0" ixz="0.0" iyy="0" iyz="0.0" izz="0"/>   <!-- ly modified -->
      <!--  <inertia ixx="0.00000" ixy="0" ixz="0" iyy="0.00000" iyz="0" izz="0.00000"/>  --> 
    </inertial>
  </link>
  <link name="allegro_root5">
    <inertial>
      <mass value="0.0"/>
       <inertia ixx="0" ixy="0.0" ixz="0.0" iyy="0" iyz="0.0" izz="0"/>   <!-- ly modified -->
      <!-- <inertia ixx="0.00000" ixy="0" ixz="0" iyy="0.00000" iyz="0" izz="0.00000"/> --> 
    </inertial>
  </link>
  
  <!-- PALM -->
  <link name="palm">
    <inertial>
      <origin rpy="0 0 0" xyz="0 0 0.035" />
      <mass value="0.3" />
      <inertia ixx="0.5" ixy="0.0" ixz="0.0" iyy="0.5" iyz="0.0" izz="0.3" />
    </inertial>
    <visual>
      <origin rpy="0 0 0" xyz="0 0 0" />
      <geometry name="palm_visual">
        <mesh filename="meshes/palm.obj"/>
      </geometry>
      <material name="Grey" />
    </visual>
    <collision>
      <origin rpy="0 0 0" xyz="0.005 0 0.035" />
      <geometry name="palm_collision_geom">
        <box size="0.05 0.02 0.07" />
      </geometry>
      <material name="">
        <contact name="finger"/>
      </material>
    </collision>
  </link>

  <joint name="x_joint" type="prismatic">
    <parent link="allegro_root0"/>
    <child link="allegro_root1"/>
    <axis xyz="1 0 0"/>
    <limit lower="-0.5" upper="0.5"/>
    <dynamics damping="10.0" friction="0.0001"/>
    <!-- <dynamics damping="100.5" />   ly modified -->
  </joint>
  <joint name="y_joint" type="prismatic">
    <parent link="allegro_root1"/>
    <child link="allegro_root2"/>
    <axis xyz="0 1 0"/>
    <limit lower="-0.5" upper="0.5"/>
    <dynamics damping="10.0" friction="0.0001"/>
    <!-- <dynamics damping="100.5" /> ly modified -->
  </joint>
  <joint name="z_joint" type="prismatic">
    <parent link="allegro_root2"/>
    <child link="allegro_root3"/>
    <axis xyz="0 0 1"/>
    <limit lower="-0.5" upper="0.5"/>
    <dynamics damping="10.0" friction="0.0001"/>
    <!-- <dynamics damping="100.5" />   ly modified -->
  </joint>
  <joint name="x_rotation_joint" type="revolute">
    <parent link="allegro_root3"/>
    <child link="allegro_root4"/>
    <axis xyz="1 0 0"/>
    <limit lower="-3.14" upper="3.14"/>
    <dynamics   damping="1.0" friction="0.0001"/>
    <!-- <dynamics damping="100.5" />  ly modified -->
  </joint>
  <joint name="y_rotation_joint" type="revolute">
    <parent link="allegro_root4"/>
    <child link="allegro_root5"/>
    <axis xyz="0 1 0"/>
    <limit lower="-3.14" upper="3.14"/>
    <dynamics   damping="1.0" friction="0.0001"/>
    <!-- <dynamics damping="100.5" />  ly modified -->
  </joint>
  <joint name="z_rotation_joint" type="revolute">
    <parent link="allegro_root5"/>
    <child link="palm"/>
    <axis xyz="0 0 1"/>
    <limit lower="-3.14" upper="3.14"/>
    <dynamics   damping="1.0" friction="0.0001"/>
    <!-- <dynamics damping="100.5" />ly modified -->
  </joint>

  <!-- FINGERS -->
  <link name="ffknuckle">
    <inertial>
      <origin rpy="0 0 0" xyz="0 0 0" />
      <mass value="0.008" />
      <inertia ixx="0.0" ixy="0.0" ixz="0.0" iyy="0.1" iyz="0.0" izz="0.0" />
    </inertial>
    <visual>
      <origin rpy="0 0 0" xyz="0 0 0.0005" />
      <geometry name="knuckle_visual">
        <mesh filename="meshes/knuckle.obj"/>
      </geometry>
      <material name="LightGrey" />
    </visual>
    <collision>
      <origin rpy="0 0 0" xyz="0 0 0" />
      <geometry name="knuckle_collision_geom">
        <box size="0.005 0.005 0.005" />
      </geometry>
      <material name="">
        <contact name="finger"/>
      </material>
    </collision>
  </link>
  <joint name="FFJ4" type="revolute">
    <parent link="palm" />
    <child link="ffknuckle" />
    <origin rpy="0 0 0" xyz="0.033 0 0.095" />
    <axis xyz="0 -1 0" />
    <limit effort="100" lower="-0.43633231299858238" upper="0.43633231299858238" velocity="1.0" />
    <dynamics damping="1.0" />
  </joint>
  <link name="ffproximal">
    <inertial>
      <mass value="0.014" />
      <origin xyz="0 0 0.0225" />
      <inertia ixx="0.1" ixy="0.0" ixz="0.0" iyy="0.1" iyz="0.0" izz="0.0" />
    </inertial>
    <visual>
      <origin rpy="0 0 0" xyz="0 0 0" />
      <geometry name="proximal_visual">
        <mesh filename="meshes/F3.obj"/>
      </geometry>
      <material name="Grey" />
    </visual>
    <collision>
      <origin rpy="0 0 0 " xyz="0 0 0.025" />
      <geometry name="proximal_collision_geom">
        <box size="0.015 0.015 0.03" />
      </geometry>
      <material name="">
        <contact name="finger"/>
      </material>
    </collision>
  </link>
  <joint name="FFJ3" type="revolute">
    <parent link="ffknuckle" />
    <child link="ffproximal" />
    <origin rpy="0 0 0" xyz="0 0 0" />
    <axis xyz="1 0 0" />
    <limit effort="100" lower="0" upper="1.57079632679" velocity="1.0" />
    <dynamics damping="1.0" />
  </joint>
  <link name="ffmiddle">
    <inertial>
      <origin rpy="0 0 0" xyz="0 0 0.0125" />
      <mass value="0.012" />
      <inertia ixx="0.1" ixy="0.0" ixz="0.0" iyy="0.1" iyz="0.0" izz="0.0" />
    </inertial>
    <visual>
      <origin rpy="0 0 0" xyz="0 0 0" />
      <geometry name="middle_visual">
        <mesh filename="meshes/F2.obj"/>
      </geometry>
      <material name="Grey" />
    </visual>
    <collision>
      <origin rpy="0 0 0" xyz="0 0 0.0125" />
      <geometry name="middle_collision_geom">
        <box size="0.015 0.015 0.015" />
      </geometry>
      <material name="">
        <contact name="finger"/>
      </material>
    </collision>
  </link>
  <joint name="FFJ2" type="revolute">
    <parent link="ffproximal" />
    <child link="ffmiddle" />
    <origin rpy="0 0 0" xyz="0 0 0.045" />
    <axis xyz="1 0 0" />
    <limit effort="100" lower="0" upper="1.57079632679" velocity="1.0" />
    <dynamics damping="1.0" />
  </joint>
  <link name="ffdistal">
    <inertial>
      <mass value="0.010" />
      <origin xyz="0 0 0.013" />
      <inertia ixx="0.1" ixy="0.0" ixz="0.0" iyy="0.1" iyz="0.0" izz="0.0" />
    </inertial>
    <visual>
      <origin rpy="0 0 0" xyz="0 0 0" />
      <geometry name="distal_visual">
        <mesh filename="meshes/distal_ellipsoid.obj"/>
      </geometry>
      <material name="Grey" />
    </visual>
    <collision>
      <origin rpy="0 0 0" xyz="0 0 0" />
      <geometry name="distal_collision_geom">
        <mesh filename="meshes/distal_ellipsoid.obj"/>
      </geometry>
      <material name="">
        <contact name="finger"/>
      </material>
    </collision>
  </link>
  <joint name="FFJ1" type="revolute">
    <parent link="ffmiddle" />
    <child link="ffdistal" />
    <origin rpy="0 0 0" xyz="0 0 0.025" />
    <axis xyz="1 0 0" />
    <limit effort="100" lower="0" upper="1.57079632679" velocity="1.0" />
    <dynamics damping="1.0" />
  </joint>
  <link name="fftip">
    <inertial>
      <mass value="0.001" />
      <inertia ixx="0.0" ixy="0.0" ixz="0.0" iyy="0.0" iyz="0.0" izz="0.0" />
    </inertial>
  </link>
  <joint name="FFtip" type="fixed">
    <parent link="ffdistal" />
    <child link="fftip" />
    <origin rpy="0 0 0" xyz="0 0 0.026" />
  </joint>

  <!-- ly test: change contact point position -->
  <link name="fftip_back">
  </link>
  <joint name="FFtip_back" type="fixed">
    <parent link="fftip" />
    <child link="fftip_back" />
    <origin rpy="0 0 0" xyz="0 0 -0.013" />
  </joint>


  <link name="mfknuckle">
    <inertial>
      <origin rpy="0 0 0" xyz="0 0 0" />
      <mass value="0.008" />
      <inertia ixx="0.0" ixy="0.0" ixz="0.0" iyy="0.1" iyz="0.0" izz="0.0" />
    </inertial>
    <visual>
      <origin rpy="0 0 0" xyz="0 0 0.0005" />
      <geometry name="knuckle_visual">
        <mesh filename="meshes/knuckle.obj"/>
      </geometry>
      <material name="LightGrey" />
    </visual>
    <collision>
      <origin rpy="0 0 0" xyz="0 0 0" />
      <geometry name="knuckle_collision_geom">
        <box size="0.005 0.005 0.005" />
      </geometry>
      <material name="">
        <contact name="finger"/>
      </material>
    </collision>
  </link>
  <joint name="MFJ4" type="revolute">
    <parent link="palm" />
    <child link="mfknuckle" />

    <origin rpy="0 0 0" xyz="0.011 0 0.099" />
    <axis xyz="0 -1 0" />
    <limit effort="100" lower="-0.43633231299858238" upper="0.43633231299858238" velocity="1.0" />
    <dynamics damping="1.0" />
  </joint>
  <link name="mfproximal">
    <inertial>
      <mass value="0.014" />
      <origin xyz="0 0 0.0225" />
      <inertia ixx="0.1" ixy="0.0" ixz="0.0" iyy="0.1" iyz="0.0" izz="0.0" />
    </inertial>
    <visual>
      <origin rpy="0 0 0" xyz="0 0 0" />
      <geometry name="proximal_visual">
        <mesh filename="meshes/F3.obj"/>
      </geometry>
      <material name="Grey" />
    </visual>
    <collision>
      <origin rpy="0 0 0 " xyz="0 0 0.025" />
      <geometry name="proximal_collision_geom">
        <box size="0.015 0.015 0.03" />
      </geometry>
      <material name="">
        <contact name="finger"/>
      </material>
    </collision>
  </link>
  <joint name="MFJ3" type="revolute">
    <parent link="mfknuckle" />
    <child link="mfproximal" />
    <origin rpy="0 0 0" xyz="0 0 0" />
    <axis xyz="1 0 0" />
    <limit effort="100" lower="0" upper="1.57079632679" velocity="1.0" />
    <dynamics damping="1.0" />
  </joint>
  <link name="mfmiddle">
    <inertial>
      <origin rpy="0 0 0" xyz="0 0 0.0125" />
      <mass value="0.012" />
      <inertia ixx="0.1" ixy="0.0" ixz="0.0" iyy="0.1" iyz="0.0" izz="0.0" />
    </inertial>
    <visual>
      <origin rpy="0 0 0" xyz="0 0 0" />
      <geometry name="middle_visual">
        <mesh filename="meshes/F2.obj"/>
      </geometry>
      <material name="Grey" />
    </visual>
    <collision>
      <origin rpy="0 0 0" xyz="0 0 0.0125" />
      <geometry name="middle_collision_geom">
        <box size="0.015 0.015 0.015" />
      </geometry>
      <material name="">
        <contact name="finger"/>
      </material>
    </collision>
  </link>
  <joint name="MFJ2" type="revolute">
    <parent link="mfproximal" />
    <child link="mfmiddle" />
    <origin rpy="0 0 0" xyz="0 0 0.045" />
    <axis xyz="1 0 0" />
    <limit effort="100" lower="0" upper="1.57079632679" velocity="1.0" />
    <dynamics damping="1.0" />
  </joint>
  <link name="mfdistal">
    <inertial>
      <mass value="0.010" />
      <origin xyz="0 0 0.013" />
      <inertia ixx="0.1" ixy="0.0" ixz="0.0" iyy="0.1" iyz="0.0" izz="0.0" />
    </inertial>
    <visual>
      <origin rpy="0 0 0" xyz="0 0 0" />
      <geometry name="distal_visual">
        <mesh filename="meshes/F1.obj"/>
      </geometry>
      <material name="Grey" />
    </visual>
    <collision>
      <origin rpy="0 0 0" xyz="0 0 0" />
      <geometry name="distal_collision_geom">
        <mesh filename="meshes/F1.obj"/>
      </geometry>
      <material name="">
        <contact name="finger"/>
      </material>
    </collision>
  </link>
  <joint name="MFJ1" type="revolute">
    <parent link="mfmiddle" />
    <child link="mfdistal" />
    <origin rpy="0 0 0" xyz="0 0 0.025" />
    <axis xyz="1 0 0" />
    <limit effort="100" lower="0" upper="1.57079632679" velocity="1.0" />
    <dynamics damping="1.0" />
  </joint>
  <link name="mftip">
    <inertial>
      <mass value="0.001" />
      <inertia ixx="0.0" ixy="0.0" ixz="0.0" iyy="0.0" iyz="0.0" izz="0.0" />
    </inertial>
  </link>
  <joint name="MFtip" type="fixed">
    <parent link="mfdistal" />
    <child link="mftip" />
    <origin rpy="0 0 0" xyz="0 0 0.026" />
  </joint>

  <!-- ly test: change contact point position -->
  <link name="mftip_back">
  </link>
  <joint name="MFtip_back" type="fixed">
    <parent link="mftip" />
    <child link="mftip_back" />
    <origin rpy="0 0 0" xyz="0 0 -0.013" />
  </joint>

  <link name="rfknuckle">
    <inertial>
      <origin rpy="0 0 0" xyz="0 0 0" />
      <mass value="0.008" />
      <inertia ixx="0.0" ixy="0.0" ixz="0.0" iyy="0.1" iyz="0.0" izz="0.0" />
    </inertial>
    <visual>
      <origin rpy="0 0 0" xyz="0 0 0.0005" />
      <geometry name="knuckle_visual">
        <mesh filename="meshes/knuckle.obj"/>
      </geometry>
      <material name="LightGrey" />
    </visual>
    <collision>
      <origin rpy="0 0 0" xyz="0 0 0" />
      <geometry name="knuckle_collision_geom">
        <box size="0.005 0.005 0.005" />
      </geometry>
      <material name="">
        <contact name="finger"/>
      </material>
    </collision>
  </link>
  <joint name="RFJ4" type="revolute">
    <parent link="palm" />
    <child link="rfknuckle" />
    <origin rpy="0 0 0" xyz="-0.011 0 0.095" />
    <axis xyz="0 1 0" />
    <limit effort="100" lower="-0.43633231299858238" upper="0.43633231299858238" velocity="1.0" />
    <dynamics damping="1.0" />
  </joint>
  <link name="rfproximal">
    <inertial>
      <mass value="0.014" />
      <origin xyz="0 0 0.0225" />
      <inertia ixx="0.1" ixy="0.0" ixz="0.0" iyy="0.1" iyz="0.0" izz="0.0" />
    </inertial>
    <visual>
      <origin rpy="0 0 0" xyz="0 0 0" />
      <geometry name="proximal_visual">
        <mesh filename="meshes/F3.obj"/>
      </geometry>
      <material name="Grey" />
    </visual>
    <collision>
      <origin rpy="0 0 0 " xyz="0 0 0.025" />
      <geometry name="proximal_collision_geom">
        <box size="0.015 0.015 0.03" />
      </geometry>
      <material name="">
        <contact name="finger"/>
      </material>
    </collision>
  </link>
  <joint name="RFJ3" type="revolute">
    <parent link="rfknuckle" />
    <child link="rfproximal" />
    <origin rpy="0 0 0" xyz="0 0 0" />
    <axis xyz="1 0 0" />
    <limit effort="100" lower="0" upper="1.57079632679" velocity="1.0" />
    <dynamics damping="1.0" />
  </joint>
  <link name="rfmiddle">
    <inertial>
      <origin rpy="0 0 0" xyz="0 0 0.0125" />
      <mass value="0.012" />
      <inertia ixx="0.1" ixy="0.0" ixz="0.0" iyy="0.1" iyz="0.0" izz="0.0" />
    </inertial>
    <visual>
      <origin rpy="0 0 0" xyz="0 0 0" />
      <geometry name="middle_visual">
        <mesh filename="meshes/F2.obj"/>
      </geometry>
      <material name="Grey" />
    </visual>
    <collision>
      <origin rpy="0 0 0" xyz="0 0 0.0125" />
      <geometry name="middle_collision_geom">
        <box size="0.015 0.015 0.015" />
      </geometry>
      <material name="">
        <contact name="finger"/>
      </material>
    </collision>
  </link>
  <joint name="RFJ2" type="revolute">
    <parent link="rfproximal" />
    <child link="rfmiddle" />
    <origin rpy="0 0 0" xyz="0 0 0.045" />
    <axis xyz="1 0 0" />
    <limit effort="100" lower="0" upper="1.57079632679" velocity="1.0" />
    <dynamics damping="1.0" />
  </joint>
  <link name="rfdistal">
    <inertial>
      <mass value="0.010" />
      <origin xyz="0 0 0.013" />
      <inertia ixx="0.1" ixy="0.0" ixz="0.0" iyy="0.1" iyz="0.0" izz="0.0" />
    </inertial>
    <visual>
      <origin rpy="0 0 0" xyz="0 0 0" />
      <geometry name="distal_visual">
        <mesh filename="meshes/distal_ellipsoid.obj"/>
      </geometry>
      <material name="Grey" />
    </visual>

    <collision>
      <origin rpy="0 0 0" xyz="0 0 0" />
      <geometry name="distal_collision_geom">
        <mesh filename="meshes/distal_ellipsoid.obj"/>
      </geometry>
      <material name="">
        <contact name="finger"/>
      </material>
    </collision>
  </link>
  <joint name="RFJ1" type="revolute">
    <parent link="rfmiddle" />
    <child link="rfdistal" />
    <origin rpy="0 0 0" xyz="0 0 0.025" />
    <axis xyz="1 0 0" />
    <limit effort="100" lower="0" upper="1.57079632679" velocity="1.0" />
    <dynamics damping="1.0" />
  </joint>
  <link name="rftip">
    <inertial>
      <mass value="0.001" />
      <inertia ixx="0.0" ixy="0.0" ixz="0.0" iyy="0.0" iyz="0.0" izz="0.0" />
    </inertial>
  </link>
  <joint name="RFtip" type="fixed">
    <parent link="rfdistal" />
    <child link="rftip" />
    <origin rpy="0 0 0" xyz="0 0 0.026" />
  </joint>

  <!-- ly test: change contact point position -->
  <link name="rftip_back">
  </link>
  <joint name="RFtip_back" type="fixed">
    <parent link="rftip" />
    <child link="rftip_back" />
    <origin rpy="0 0 0" xyz="0 0 -0.013" />
  </joint>

  <link name="lfmetacarpal">
    <inertial>
      <origin rpy="0 0 0" xyz="0 0 0.04" />
      <mass value="0.075" />
      <inertia ixx="0.1" ixy="0.0" ixz="0.0" iyy="0.1" iyz="0.0" izz="0.1" />
    </inertial>
    <visual>
      <origin rpy="0 0 0" xyz="0 0 0" />
      <geometry name="lfmetacarpal_visual">
        <mesh filename="meshes/lfmetacarpal.obj"/>
      </geometry>
      <material name="Grey" />
    </visual>
    <collision>
      <origin rpy="0 0 0" xyz="0 0 0.04" />
      <geometry name="lfmetacarpal_collision_geom">
        <box size="0.015 0.015 0.03" />
      </geometry>
      <material name="">
        <contact name="finger"/>
      </material>
    </collision>
  </link>
  <joint name="LFJ5" type="revolute">
    <parent link="palm" />
    <child link="lfmetacarpal" />
    <origin rpy="0 0 0" xyz="-0.033 0 0.02071" />
    <axis xyz="0.573576436 0 0.819152044" />
    <limit effort="100" lower="0" upper="0.69813170079773179" velocity="1.0" />
    <dynamics damping="1.0" />
  </joint>
  <link name="lfknuckle">
    <inertial>
      <origin rpy="0 0 0" xyz="0 0 0.06579" />
      <mass value="0.008" />
      <inertia ixx="0.1" ixy="0.0" ixz="0.0" iyy="0.1" iyz="0.0" izz="0.1" />
    </inertial>
    <visual>
      <origin rpy="0 0 0" xyz="0 0 0" />
      <geometry name="knuckle_visual">
        <mesh filename="meshes/knuckle.obj"/>
      </geometry>
      <material name="LightGrey" />
    </visual>
    <collision>
      <origin rpy="0 0 0" xyz="0 0 0" />
      <geometry name="knuckle_collision_geom">
        <box size="0.005 0.005 0.005" />
      </geometry>
      <material name="">
        <contact name="finger"/>
      </material>
    </collision>
  </link>
  <joint name="LFJ4" type="revolute">
    <parent link="lfmetacarpal" />
    <child link="lfknuckle" />
    <origin rpy="0 0 0" xyz="0 0 0.06579" />
    <axis xyz="0 1 0" />
    <limit effort="100" lower="-0.43633231299858238" upper="0.43633231299858238" velocity="1.0" />
    <dynamics damping="1.0" />
  </joint>
  <link name="lfproximal">
    <inertial>
      <mass value="0.014" />
      <origin xyz="0 0 0.0225" />
      <inertia ixx="0.1" ixy="0.0" ixz="0.0" iyy="0.1" iyz="0.0" izz="0.0" />
    </inertial>
    <visual>
      <origin rpy="0 0 0" xyz="0 0 0" />
      <geometry name="proximal_visual">
        <mesh filename="meshes/F3.obj"/>
      </geometry>
      <material name="Grey" />
    </visual>
    <collision>
      <origin rpy="0 0 0 " xyz="0 0 0.025" />
      <geometry name="proximal_collision_geom">
        <box size="0.015 0.015 0.03" />
      </geometry>
      <material name="">
        <contact name="finger"/>
      </material>
    </collision>
  </link>
  <joint name="LFJ3" type="revolute">
    <parent link="lfknuckle" />
    <child link="lfproximal" />
    <origin rpy="0 0 0" xyz="0 0 0" />
    <axis xyz="1 0 0" />
    <limit effort="100" lower="0" upper="1.57079632679" velocity="1.0" />
    <dynamics damping="1.0" />
  </joint>
  <link name="lfmiddle">
    <inertial>
      <origin rpy="0 0 0" xyz="0 0 0.0125" />
      <mass value="0.012" />
      <inertia ixx="0.1" ixy="0.0" ixz="0.0" iyy="0.1" iyz="0.0" izz="0.0" />
    </inertial>
    <visual>
      <origin rpy="0 0 0" xyz="0 0 0" />
      <geometry name="middle_visual">
        <mesh filename="meshes/F2.obj"/>
      </geometry>
      <material name="Grey" />
    </visual>
    <collision>
      <origin rpy="0 0 0" xyz="0 0 0.0125" />
      <geometry name="middle_collision_geom">
        <box size="0.015 0.015 0.015" />
      </geometry>
      <material name="">
        <contact name="finger"/>
      </material>
    </collision>
  </link>
  <joint name="LFJ2" type="revolute">
    <parent link="lfproximal" />
    <child link="lfmiddle" />
    <origin rpy="0 0 0" xyz="0 0 0.045" />
    <axis xyz="1 0 0" />
    <limit effort="100" lower="0" upper="1.57079632679" velocity="1.0" />
    <dynamics damping="1.0" />
  </joint>
  <link name="lfdistal">
    <inertial>
      <mass value="0.010" />
      <origin xyz="0 0 0.013" />
      <inertia ixx="0.1" ixy="0.0" ixz="0.0" iyy="0.1" iyz="0.0" izz="0.0" />
    </inertial>
    <visual>
      <origin rpy="0 0 0" xyz="0 0 0" />
      <geometry name="distal_visual">
        <mesh filename="meshes/F1.obj"/>
      </geometry>
      <material name="Grey" />
    </visual>

    <collision>
      <origin rpy="0 0 0" xyz="0 0 0" />
      <geometry name="distal_collision_geom">
        <mesh filename="meshes/F1.obj"/>
      </geometry>
      <material name="">
        <contact name="finger"/>
      </material>
    </collision>
  </link>
  <joint name="LFJ1" type="revolute">
    <parent link="lfmiddle" />
    <child link="lfdistal" />
    <origin rpy="0 0 0" xyz="0 0 0.025" />
    <axis xyz="1 0 0" />
    <limit effort="100" lower="0" upper="1.57079632679" velocity="1.0" />
    <dynamics damping="1.0" />
  </joint>
  <link name="lftip">
    <inertial>
      <mass value="0.001" />
      <inertia ixx="0.0" ixy="0.0" ixz="0.0" iyy="0.0" iyz="0.0" izz="0.0" />
    </inertial>
  </link>
  <joint name="LFtip" type="fixed">
    <parent link="lfdistal" />
    <child link="lftip" />
    <origin rpy="0 0 0" xyz="0 0 0.026" />
  </joint>

  <!-- ly test: change contact point position -->
  <link name="lftip_back">
  </link>
  <joint name="LFtip_back" type="fixed">
    <parent link="lftip" />
    <child link="lftip_back" />
    <origin rpy="0 0 0" xyz="0 0 -0.013" />
  </joint>

  <link name="thbase">
    <inertial>
      <mass value="0.010" />
      <origin rpy="0 0 0" xyz="0 0 0" />
      <inertia ixx="0.0" ixy="0.0" ixz="0.0" iyy="0.0" iyz="0.0" izz="0.1" />
    </inertial>
    <visual>
      <origin rpy="0 0 0" xyz="0 0 0" />
      <geometry name="thbase_visual">
        <box size="0.001 0.001 0.001" />
      </geometry>
      <material name="shadow_thbase_material">
        <color rgba="0.5 0.5 0.5 1.0" />
      </material>
    </visual>
    <collision>
      <origin rpy="0 0 0 " xyz="0 0 0" />
      <geometry name="thbase_collision_geom">
        <box size="0.001 0.001 0.001" />
      </geometry>
      <material name="">
        <contact name="finger"/>
      </material>
    </collision>
  </link>
  <joint name="THJ5" type="revolute">
    <parent link="palm" />
    <child link="thbase" />
    <origin rpy="0 0.785398163397 0" xyz="0.034 -0.0085 0.029" />
    <axis xyz="0 0 -1.0" />
    <limit effort="100" lower="-1.047" upper="1.047" velocity="1.0" />
    <dynamics damping="1.0" />
  </joint>
  <link name="thproximal">
    <inertial>
      <mass value="0.016" />
      <origin rpy="0 0 0" xyz="0 0 0.019" />
      <inertia ixx="0.1" ixy="0.0" ixz="0.0" iyy="0.1" iyz="0.0" izz="0.1" />
    </inertial>
    <visual>
      <origin rpy="0 0 0" xyz="0 0 0" />
      <geometry name="thproximal_visual">
        <mesh filename="meshes/TH3_z.obj"/>
      </geometry>
      <material name="shadow_thproximal_material">
        <color rgba="0.2 0.2 0.2 1.0" />
      </material>
    </visual>
    <collision>
      <origin rpy="0 0 0" xyz="0 0 0.019" />
      <geometry name="thproximal_collision_geom">
        <box size="0.015 0.015 0.020" />
      </geometry>
      <material name="">
        <contact name="finger"/>
      </material>
    </collision>
  </link>
  <joint name="THJ4" type="revolute">
    <parent link="thbase" />
    <child link="thproximal" />
    <origin rpy="0 0 0" xyz="0 0 0" />
    <axis xyz="1.0 0 0" />
    <limit effort="100" lower="0" upper="1.309" velocity="1.0" />
    <dynamics damping="1.0" />
  </joint>
  <link name="thhub">
    <inertial>
      <mass value="0.002" />
      <origin rpy="0 0 0" xyz="0 0 0" />
      <inertia ixx="0.1" ixy="0.0" ixz="0.0" iyy="0.1" iyz="0.0" izz="0.1" />
    </inertial>
    <visual>
      <origin rpy="0 0 0" xyz="0 0 0" />
      <geometry name="thhub_visual">
        <box size="0.001 0.001 0.001" />
      </geometry>
      <material name="shadow_thhub_material">
        <color rgba="0.7 0.7 0.7 1.0" />
      </material>
    </visual>
    <collision>
      <origin rpy="0 0 0 " xyz="0 0 0" />
      <geometry name="thhub_collision_geom">
        <box size="0.001 0.001 0.001" />
      </geometry>
      <material name="">
        <contact name="finger"/>
      </material>
    </collision>
  </link>
  <joint name="THJ3" type="revolute">
    <parent link="thproximal" />
    <child link="thhub" />
    <origin rpy="0 0 0" xyz="0 0 0.038" />
    <axis xyz="1 0 0" />
    <limit effort="100" lower="-0.2618" upper="0.2618" velocity="1.0" />
    <dynamics damping="1.0" />
  </joint>
  <link name="thmiddle">
    <inertial>
      <mass value="0.016" />
      <origin rpy="0 0 0" xyz="0 0 0.016" />
      <inertia ixx="0.1" ixy="0.0" ixz="0.0" iyy="0.1" iyz="0.0" izz="0.1" />
    </inertial>
    <visual>
      <origin rpy="0 0 0" xyz="0 0 0" />
      <geometry name="thmiddle_visual">
        <mesh filename="meshes/TH2_z.obj"/>
      </geometry>
      <material name="shadow_thmiddle_material">
        <color rgba="0.2 0.2 0.2 1.0" />
      </material>
    </visual>
    <collision>
      <origin rpy="0 0 0 " xyz="0 0 0.016" />
      <geometry name="thmiddle_collision_geom">
        <box size="0.015 0.015 0.015" />
      </geometry>
      <material name="">
        <contact name="finger"/>
      </material>
    </collision>
  </link>
  <joint name="THJ2" type="revolute">
    <parent link="thhub" />
    <child link="thmiddle" />
    <origin rpy="0 0 0" xyz="0 0 0" />
    <axis xyz="0 -1 0" />
    <limit effort="100" lower="-0.5237" upper="0.5237" velocity="1.0" />
    <dynamics damping="1.0" />
  </joint>
  <link name="thdistal">
    <inertial>
      <mass value="0.016" />
      <origin rpy="0 0 0" xyz="0 0 0.01375" />
      <inertia ixx="0.1" ixy="0.0" ixz="0.0" iyy="0.1" iyz="0.0" izz="0.1" />
    </inertial>
    <visual>
      <origin rpy="0 0 0" xyz="0 0.002 0.0025" />
      <geometry name="thdistal_visual">
        <mesh filename="meshes/distal_ellipsoid.obj"/>
      </geometry>
      <material name="shadow_thmiddle_material">
        <color rgba="0.2 0.2 0.2 1.0" />
      </material>
    </visual>
    <collision>
      <origin rpy="0 0 0 " xyz="0 0.002 0.0025" />
      <geometry name="thmiddle_collision_geom">
        <mesh filename="meshes/distal_ellipsoid.obj"/>
      </geometry>
      <material name="">
        <contact name="finger"/>
      </material>
    </collision>
  </link>
  <joint name="THJ1" type="revolute">
    <parent link="thmiddle" />
    <child link="thdistal" />
    <origin rpy="0 0 -1.570796327" xyz="0 0 0.032" />
    <axis xyz="1 0 0" />
    <limit effort="100" lower="0" upper="1.571" velocity="1.0" />
    <dynamics damping="1.0" />
  </joint>
  <link name="thtip">
    <inertial>
      <mass value="0.001" />
      <inertia ixx="0.0" ixy="0.0" ixz="0.0" iyy="0.0" iyz="0.0" izz="0.0" />
    </inertial>
  </link>
  <joint name="thtip" type="fixed">
    <parent link="thdistal" />
    <child link="thtip" />
    <origin rpy="0 0 0" xyz="0 0 0.0275" />
  </joint>

  <!-- ly test: change contact point position -->
  <link name="thtip_back">
  </link>
  <joint name="THtip_back" type="fixed">
    <parent link="thtip" />
    <child link="thtip_back" />
    <origin rpy="0 0 0" xyz="0 0 -0.01375" />
  </joint>

  </robot>
